import { Request, Response, NextFunction } from 'express';
import { logger } from '../utils/logger';

export class AppError extends Error {
  constructor(
    public statusCode: number,
    public message: string,
    public code?: string,
    public details?: any
  ) {
    super(message);
    this.name = 'AppError';
    Error.captureStackTrace(this, this.constructor);
  }
}

export const errorHandler = (
  err: Error | AppError,
  req: Request,
  res: Response,
  _next: NextFunction
): void => {
  if (err instanceof AppError) {
    logger.error({
      message: err.message,
      code: err.code,
      statusCode: err.statusCode,
      details: err.details,
      path: req.path,
      method: req.method
    });

    res.status(err.statusCode).json({
      success: false,
      error: {
        code: err.code || 'INTERNAL_ERROR',
        message: err.message,
        details: err.details
      }
    });
  } else {
    logger.error({
      message: err.message,
      stack: err.stack,
      path: req.path,
      method: req.method
    });

    res.status(500).json({
      success: false,
      error: {
        code: 'INTERNAL_ERROR',
        message: 'An unexpected error occurred'
      }
    });
  }
};

export const asyncHandler = (fn: Function) => (
  req: Request,
  res: Response,
  next: NextFunction
) => {
  Promise.resolve(fn(req, res, next)).catch(next);
};